<?xml version="1.0" ?>
<robot name="locobot_lite">
    <link name="base_footprint">
        <visual>
            <origin rpy="0 0 0" xyz="0 0 0"/>
            <geometry>
                <box size="0.001 0.001 0.001"/>
            </geometry>
            <material name="Green"/>
        </visual>
        <collision>
            <origin rpy="0 0 0" xyz="0 0 0.017"/>
            <geometry>
                <box size="0.001 0.001 0.001"/>
            </geometry>
        </collision>
    </link>
    <link name="base_link">
        <inertial>
            <mass value="20"/>
            <origin xyz="0 0 0.0"/>
            <inertia ixx="0.1" ixy="0.0" ixz="0.0" iyy="0.1" iyz="0.0" izz="5"/>
            <!--<mass value="2"/>-->
            <!--<origin xyz="0 0 0.0"/>-->
            <!--<inertia ixx="0.01" ixy="0.0" ixz="0.0" iyy="0.01" iyz="0.0" izz="0.5"/>-->
        </inertial>
        <visual>
            <origin rpy="0 0 0" xyz=" 0 0 0.0308"/>
            <geometry>
                <mesh filename="package://ca_description/meshes/create_2.dae"/>
            </geometry>
        </visual>
        <collision>
            <origin rpy="0 0 0" xyz="0.0 0.0 0.0308"/>
            <geometry>
                <cylinder length="0.0611632" radius="0.16495"/>
            </geometry>
        </collision>
    </link>
    <link name="wall_sensor_link">
        <inertial>
            <mass value="0.01"/>
            <origin xyz="0 0 0"/>
            <inertia ixx="0.001" ixy="0.0" ixz="0.0" iyy="0.001" iyz="0.0" izz="0.001"/>
        </inertial>
    </link>
    <link name="left_cliff_sensor_link">
        <inertial>
            <mass value="0.01"/>
            <origin xyz="0 0 0"/>
            <inertia ixx="0.001" ixy="0.0" ixz="0.0" iyy="0.001" iyz="0.0" izz="0.001"/>
        </inertial>
    </link>
    <link name="right_cliff_sensor_link">
        <inertial>
            <mass value="0.01"/>
            <origin xyz="0 0 0"/>
            <inertia ixx="0.001" ixy="0.0" ixz="0.0" iyy="0.001" iyz="0.0" izz="0.001"/>
        </inertial>
    </link>
    <link name="leftfront_cliff_sensor_link">
        <inertial>
            <mass value="0.01"/>
            <origin xyz="0 0 0"/>
            <inertia ixx="1.0" ixy="0.0" ixz="0.0" iyy="0.01" iyz="0.0" izz="0.01"/>
        </inertial>
    </link>
    <link name="rightfront_cliff_sensor_link">
        <inertial>
            <mass value="0.01"/>
            <origin xyz="0 0 0"/>
            <inertia ixx="0.001" ixy="0.0" ixz="0.0" iyy="0.001" iyz="0.0" izz="0.001"/>
        </inertial>
    </link>
    <joint name="base_footprint_joint" type="fixed">
        <origin rpy="0 0 0" xyz="0 0 0.017"/>
        <parent link="base_footprint"/>
        <child link="base_link"/>
    </joint>
    <joint name="base_wall_sensor_joint" type="fixed">
        <origin rpy="0 0 -1.0" xyz="0.09 -0.120 0.042"/>
        <parent link="base_link"/>
        <child link="wall_sensor_link"/>
    </joint>
    <joint name="base_left_cliff_sensor_joint" type="fixed">
        <origin rpy="0 1.57079632679 0" xyz="0.07 0.14 0.01"/>
        <parent link="base_link"/>
        <child link="left_cliff_sensor_link"/>
    </joint>
    <joint name="base_right_cliff_sensor_joint" type="fixed">
        <origin rpy="0 1.57079632679 0" xyz="0.07 -0.14 0.01"/>
        <parent link="base_link"/>
        <child link="right_cliff_sensor_link"/>
    </joint>
    <joint name="base_leftfront_cliff_sensor_joint" type="fixed">
        <origin rpy="0 1.57079632679 0" xyz="0.15 0.04 0.01"/>
        <parent link="base_link"/>
        <child link="leftfront_cliff_sensor_link"/>
    </joint>
    <joint name="base_rightfront_cliff_sensor_joint" type="fixed">
        <origin rpy="0 1.57079632679 0" xyz="0.15 -0.04 0.01"/>
        <parent link="base_link"/>
        <child link="rightfront_cliff_sensor_link"/>
    </joint>
    <link name="left_wheel_link">
        <inertial>
            <origin xyz="0 0 0"/>
            <mass value="0.01"/>
            <inertia ixx="0.001" ixy="0.0" ixz="0.0" iyy="0.001" iyz="0.0" izz="0.001"/>
        </inertial>
        <visual>
            <origin rpy="0 1.57079632679 1.57079632679" xyz="0 0 0"/>
            <geometry>
                <cylinder length="0.024" radius="0.036"/>
            </geometry>
        </visual>
        <collision>
            <origin rpy="0 1.57079632679 1.57079632679" xyz="0 0 0"/>
            <geometry>
                <cylinder length="0.024" radius="0.036"/>
            </geometry>
        </collision>
    </link>
    <joint name="left_wheel_joint" type="continuous">
        <origin rpy="0 0 0" xyz="0 0.1175 0.015"/>
        <parent link="base_link"/>
        <child link="left_wheel_link"/>
        <axis xyz="0 1 0"/>
    </joint>
    <link name="right_wheel_link">
        <inertial>
            <origin xyz="0 0 0"/>
            <mass value="0.01"/>
            <inertia ixx="0.001" ixy="0.0" ixz="0.0" iyy="0.001" iyz="0.0" izz="0.001"/>
        </inertial>
        <visual>
            <origin rpy="0 1.57079632679 1.57079632679" xyz="0 0 0"/>
            <geometry>
                <cylinder length="0.024" radius="0.036"/>
            </geometry>
        </visual>
        <collision>
            <origin rpy="0 1.57079632679 1.57079632679" xyz="0 0 0"/>
            <geometry>
                <cylinder length="0.024" radius="0.036"/>
            </geometry>
        </collision>
    </link>
    <joint name="right_wheel_joint" type="continuous">
        <origin rpy="0 0 0" xyz="0 -0.1175 0.015"/>
        <parent link="base_link"/>
        <child link="right_wheel_link"/>
        <axis xyz="0 1 0"/>
    </joint>
    <!--<link name="rear_wheel_link"><inertial><origin xyz="0 0 0"/><mass value="0.001" /><inertia ixx="0.0001" ixy="0.0" ixz="0.0"
         iyy="0.0001" iyz="0.0" izz="0.0001" /></inertial><visual><origin xyz="0 0 0" rpy="0 ${PI/2} ${PI/2}"/><geometry><sphere radius="0.015" /></geometry></visual><collision><origin xyz="0 0 0" rpy="0 ${PI/2} ${PI/2}" /><geometry><sphere radius="0.015" /></geometry></collision></link><joint name="rear_castor_joint" type="fixed"><origin xyz="-0.13 0 0.0" rpy="0 0 0"/><parent link="base_link"/><child link="rear_wheel_link"/><axis xyz="0 1 0"/></joint>-->
    <link name="front_wheel_link">
        <inertial>
            <origin xyz="0 0 0"/>
            <mass value="0.01"/>
            <inertia ixx="0.001" ixy="0.0" ixz="0.0" iyy="0.001" iyz="0.0" izz="0.001"/>
        </inertial>
        <visual>
            <origin rpy="0 1.57079632679 1.57079632679" xyz="0 0 0"/>
            <geometry>
                <sphere radius="0.018"/>
            </geometry>
        </visual>
        <collision>
            <origin rpy="0 1.57079632679 1.57079632679" xyz="0 0 0"/>
            <geometry>
                <sphere radius="0.018"/>
            </geometry>
        </collision>
    </link>
    <!-- fixed because there's no transmission -->
    <joint name="front_castor_joint" type="fixed">
        <origin rpy="0 0 0" xyz="0.13 0 0.0"/>
        <parent link="base_link"/>
        <child link="front_wheel_link"/>
        <axis xyz="0 1 0"/>
    </joint>
    <joint name="gyro_joint" type="fixed">
        <axis xyz="0 1 0"/>
        <origin rpy="0 0 0" xyz="0 0 0.04"/>
        <parent link="base_link"/>
        <child link="gyro_link"/>
    </joint>
    <link name="gyro_link">
        <inertial>
            <mass value="0.001"/>
            <origin rpy="0 0 0" xyz="0 0 0"/>
            <inertia ixx="0.0001" ixy="0" ixz="0" iyy="0.000001" iyz="0" izz="0.0001"/>
        </inertial>
    </link>
    <link name="bottom_plate">
        <inertial>
            <origin rpy="0 0 0" xyz="-0.0205843558599275 1.79387705761181E-06 0.156559951996556"/>
            <mass value="0.640128902693298"/>
            <inertia ixx="0.0212697824374231" ixy="-1.84819421839641E-07" ixz="0.00177278831625861" iyy="0.0200161122874848" iyz="1.82514218153984E-07" izz="0.00538401325307411"/>
        </inertial>
        <visual>
            <origin rpy="0 0 0" xyz="0 0 0"/>
            <geometry>
                <mesh filename="package://locobot_description/meshes/base_link.STL"/>
            </geometry>
            <material name="">
                <color rgba="0.792156862745098 0.819607843137255 0.933333333333333 1"/>
            </material>
        </visual>
        <collision>
            <origin rpy="0 0 0" xyz="0 0 0"/>
            <geometry>
                <mesh filename="package://locobot_description/meshes/base_link.STL"/>
            </geometry>
        </collision>
    </link>
    <joint name="bottom_plate_joint" type="fixed">
        <origin rpy="0 0 0" xyz="0 0 0.075"/>
        <parent link="base_link"/>
        <child link="bottom_plate"/>
    </joint>
    <link name="head_pan_link">
        <inertial>
            <origin rpy="0 0 0" xyz="8.50014503228635E-17 5.26044163273016E-16 0.0220763562543528"/>
            <mass value="0.0182560287164671"/>
            <inertia ixx="1.32064472124948E-05" ixy="5.07660199873929E-13" ixz="1.73951721614857E-20" iyy="7.1220268903439E-06" iyz="-2.98341888573509E-21" izz="7.82545202279065E-06"/>
        </inertial>
        <visual>
            <origin rpy="0 0 0" xyz="0 0 0"/>
            <geometry>
                <mesh filename="package://locobot_description/meshes/yaw_link.STL"/>
            </geometry>
            <material name="">
                <color rgba="0.250980392156863 0.250980392156863 0.250980392156863 1"/>
            </material>
        </visual>
        <collision>
            <origin rpy="0 0 0" xyz="0 0 0"/>
            <geometry>
                <mesh filename="package://locobot_description/meshes/yaw_link.STL"/>
            </geometry>
        </collision>
    </link>
    <joint name="head_pan_joint" type="revolute">
        <origin rpy="0 0 0" xyz="-0.0154999999999999 0 0.4112625"/>
        <parent link="bottom_plate"/>
        <child link="head_pan_link"/>
        <axis xyz="0 0 1"/>
        <limit effort="1" lower="-1.57" upper="1.57" velocity="1"/>
    </joint>
    <link name="head_tilt_link">
        <inertial>
            <origin rpy="0 0 0" xyz="0.0168744200088311 -0.000442984145897884 -0.00405256422002387"/>
            <mass value="0.0547677687275323"/>
            <inertia ixx="1.07071738005716E-05" ixy="-1.46854788384565E-07" ixz="5.59529059364376E-08" iyy="1.77011620295824E-05" iyz="1.27587154712834E-09" izz="2.01583693170578E-05"/>
        </inertial>
        <visual>
            <origin rpy="0 0 0" xyz="0 0 0"/>
            <geometry>
                <mesh filename="package://locobot_description/meshes/roll_link.STL"/>
            </geometry>
            <material name="">
                <color rgba="0.792156862745098 0.819607843137255 0.933333333333333 1"/>
            </material>
        </visual>
        <collision>
            <origin rpy="0 0 0" xyz="0 0 0"/>
            <geometry>
                <mesh filename="package://locobot_description/meshes/roll_link.STL"/>
            </geometry>
        </collision>
    </link>
    <joint name="head_tilt_joint" type="revolute">
        <origin rpy="0 0 0" xyz="0 0 0.05"/>
        <parent link="head_pan_link"/>
        <child link="head_tilt_link"/>
        <axis xyz="0 1 0"/>
        <limit effort="1" lower="-1.57" upper="1.57" velocity="1"/>
    </joint>
    <link name="camera_link">
        <inertial>
            <origin rpy="0 0 0" xyz="-0.0132722976093535 0.00168171470080143 2.49829664994428E-06"/>
            <mass value="0.0381925651163644"/>
            <inertia ixx="2.4688255642946E-05" ixy="1.60697655569215E-07" ixz="1.2993241737711E-08" iyy="3.66669176935806E-06" iyz="1.30215657011203E-08" izz="2.48602467766615E-05"/>
        </inertial>
        <visual>
            <origin rpy="0 0 0" xyz="0 0 0"/>
            <geometry>
                <mesh filename="package://locobot_description/meshes/camera_link.STL"/>
            </geometry>
            <material name="">
                <color rgba="0.792156862745098 0.819607843137255 0.933333333333333 1"/>
            </material>
        </visual>
        <collision>
            <origin rpy="0 0 0" xyz="0 0 0"/>
            <geometry>
                <mesh filename="package://locobot_description/meshes/camera_link.STL"/>
            </geometry>
        </collision>
    </link>
    <joint name="camera_joint" type="fixed">
        <origin rpy="0 0 0" xyz="0.06705 0 -0.00425"/>
        <parent link="head_tilt_link"/>
        <child link="camera_link"/>
        <axis xyz="0 0 0"/>
    </joint>
    <link name="arm_base_link">
        <inertial>
            <origin rpy="0 0 0" xyz="-1.86027246940057E-08 -1.84987775462994E-08 0.0400356424684456"/>
            <mass value="0.531491686912019"/>
            <inertia ixx="0.000533657400855491" ixy="-4.44205269454465E-09" ixz="2.11078566024265E-10" iyy="0.000533665698902565" iyz="5.02029005902419E-11" izz="0.00071572082392375"/>
        </inertial>
        <visual>
            <origin rpy="0 0 0" xyz="0 0 0"/>
            <geometry>
                <mesh filename="package://locobot_description/meshes/arm_base_link.STL"/>
            </geometry>
            <material name="">
                <color rgba="0.792156862745098 0.819607843137255 0.933333333333333 1"/>
            </material>
        </visual>
        <collision>
            <origin rpy="0 0 0" xyz="0 0 0"/>
            <geometry>
                <mesh filename="package://locobot_description/meshes/arm_base_link.STL"/>
            </geometry>
        </collision>
    </link>
    <joint name="arm_base_link_joint" type="fixed">
        <origin rpy="0 0 0" xyz="0.08 0 -0.00900000000000009"/>
        <parent link="bottom_plate"/>
        <child link="arm_base_link"/>
        <axis xyz="0 0 0"/>
    </joint>
    <link name="shoulder_link">
        <inertial>
            <origin rpy="0 0 0" xyz="-5.67968980068612E-05 1.09785478984274E-10 0.0228467386735302"/>
            <mass value="0.119861197293521"/>
            <inertia ixx="0.000161288180462291" ixy="7.59806211309873E-14" ixz="-1.45323090659527E-07" iyy="5.49696562437107E-05" iyz="1.81052501311883E-13" izz="0.000150800672543169"/>
        </inertial>
        <visual>
            <origin rpy="0 0 0" xyz="0 0 0"/>
            <geometry>
                <mesh filename="package://locobot_description/meshes/shoulder_link.STL"/>
            </geometry>
            <material name="">
                <color rgba="0.792156862745098 0.819607843137255 0.933333333333333 1"/>
            </material>
        </visual>
        <collision>
            <origin rpy="0 0 0" xyz="0 0 0"/>
            <geometry>
                <mesh filename="package://locobot_description/meshes/shoulder_link.STL"/>
            </geometry>
        </collision>
    </link>
    <joint name="joint_1" type="revolute">
        <origin rpy="0 0 0" xyz="0 0 0.072"/>
        <parent link="arm_base_link"/>
        <child link="shoulder_link"/>
        <axis xyz="0 0 1"/>
        <limit effort="10" lower="-1.57" upper="1.57" velocity="1"/>
    </joint>
    <link name="elbow_link">
        <inertial>
            <origin rpy="0 0 0" xyz="0.00959755948481227 -2.30930057287648E-10 0.134296795349987"/>
            <mass value="0.212482745791037"/>
            <inertia ixx="0.0011748973771367" ixy="-4.7094567420817E-13" ixz="-0.000132188939134774" iyy="0.00122350302249847" iyz="-5.48932537472287E-12" izz="9.02202689343621E-05"/>
        </inertial>
        <visual>
            <origin rpy="0 0 0" xyz="0 0 0"/>
            <geometry>
                <mesh filename="package://locobot_description/meshes/elbow_link.STL"/>
            </geometry>
            <material name="">
                <color rgba="0.792156862745098 0.819607843137255 0.933333333333333 1"/>
            </material>
        </visual>
        <collision>
            <origin rpy="0 0 0" xyz="0 0 0"/>
            <geometry>
                <mesh filename="package://locobot_description/meshes/elbow_link.STL"/>
            </geometry>
        </collision>
    </link>
    <joint name="joint_2" type="revolute">
        <origin rpy="0 0 0" xyz="0 0 0.04125"/>
        <parent link="shoulder_link"/>
        <child link="elbow_link"/>
        <axis xyz="0 1 0"/>
        <limit effort="10" lower="-1.57" upper="1.57" velocity="1"/>
    </joint>
    <link name="forearm_link">
        <inertial>
            <origin rpy="0 0 0" xyz="0.117829826272582 3.09310973110905E-15 -1.26218883678142E-08"/>
            <mass value="0.18746427435805"/>
            <inertia ixx="3.94142667601686E-05" ixy="-3.65830967659785E-19" ixz="9.25852572167442E-11" iyy="0.000725209569605637" iyz="-1.05290858715495E-18" izz="0.000737165881391993"/>
        </inertial>
        <visual>
            <origin rpy="0 0 0" xyz="0 0 0"/>
            <geometry>
                <mesh filename="package://locobot_description/meshes/forearm_link.STL"/>
            </geometry>
            <material name="">
                <color rgba="0.792156862745098 0.819607843137255 0.933333333333333 1"/>
            </material>
        </visual>
        <collision>
            <origin rpy="0 0 0" xyz="0 0 0"/>
            <geometry>
                <mesh filename="package://locobot_description/meshes/forearm_link.STL"/>
            </geometry>
        </collision>
    </link>
    <joint name="joint_3" type="revolute">
        <origin rpy="0 0 0" xyz="0.05 0 0.2"/>
        <parent link="elbow_link"/>
        <child link="forearm_link"/>
        <axis xyz="0 1 0"/>
        <limit effort="10" lower="-1.57" upper="1.57" velocity="1"/>
    </joint>
    <link name="wrist_link">
        <inertial>
            <origin rpy="0 0 0" xyz="0.0429410028407894 4.98644733821042E-05 0.0114266948023652"/>
            <mass value="0.0605921736680362"/>
            <inertia ixx="1.84998512056284E-05" ixy="-1.03256667343112E-08" ixz="-1.71865409274096E-06" iyy="2.08955068262134E-05" iyz="5.05203399787143E-09" izz="1.97857037442992E-05"/>
        </inertial>
        <visual>
            <origin rpy="0 0 0" xyz="0 0 0"/>
            <geometry>
                <mesh filename="package://locobot_description/meshes/wrist_link.STL"/>
            </geometry>
            <material name="">
                <color rgba="0.792156862745098 0.819607843137255 0.933333333333333 1"/>
            </material>
        </visual>
        <collision>
            <origin rpy="0 0 0" xyz="0 0 0"/>
            <geometry>
                <mesh filename="package://locobot_description/meshes/wrist_link.STL"/>
            </geometry>
        </collision>
    </link>
    <joint name="joint_4" type="revolute">
        <origin rpy="0 0 0" xyz="0.2002 0 0"/>
        <parent link="forearm_link"/>
        <child link="wrist_link"/>
        <axis xyz="0 1 0"/>
        <limit effort="1" lower="-1.57" upper="1.57" velocity="1"/>
    </joint>
    <link name="gripper_link">
        <inertial>
            <origin rpy="0 0 0" xyz="0.0311572802112565 -1.25977280754998E-05 0.0092307003092138"/>
            <mass value="0.0795745052466434"/>
            <inertia ixx="3.27413333929741E-05" ixy="3.7314060486416E-08" ixz="3.97669066588691E-06" iyy="4.47182985231326E-05" iyz="-9.49992756213297E-09" izz="5.02142570756738E-05"/>
        </inertial>
        <visual>
            <origin rpy="0 0 0" xyz="0 0 0"/>
            <geometry>
                <mesh filename="package://locobot_description/meshes/gripper_link.STL"/>
            </geometry>
            <material name="">
                <color rgba="0.792156862745098 0.819607843137255 0.933333333333333 1"/>
            </material>
        </visual>
        <collision>
            <origin rpy="0 0 0" xyz="0 0 0"/>
            <geometry>
                <mesh filename="package://locobot_description/meshes/gripper_link.STL"/>
            </geometry>
        </collision>
    </link>
    <joint name="joint_5" type="revolute">
        <origin rpy="0 0 0" xyz="0.063 0.0001 0"/>
        <parent link="wrist_link"/>
        <child link="gripper_link"/>
        <axis xyz="-1 0 0"/>
        <limit effort="1" lower="-1.57" upper="1.57" velocity="1"/>
    </joint>
    <link name="finger_r">
        <inertial>
            <origin rpy="0 0 0" xyz="0.0100191457715113 -0.00843835347348892 -0.00483280251641866"/>
            <mass value="0.0121931459003602"/>
            <inertia ixx="6.74016278931418E-07" ixy="-2.36459038775023E-07" ixz="3.1480125304693E-09" iyy="3.10966297287339E-06" iyz="1.19271018871704E-10" izz="2.77935600332309E-06"/>
        </inertial>
        <visual>
            <origin rpy="0 0 0" xyz="0 0 0"/>
            <geometry>
                <mesh filename="package://locobot_description/meshes/finger_r.STL"/>
            </geometry>
            <material name="">
                <color rgba="0.792156862745098 0.819607843137255 0.933333333333333 1"/>
            </material>
        </visual>
        <collision>
            <origin rpy="0 0 0" xyz="0 0 0"/>
            <geometry>
                <mesh filename="package://locobot_description/meshes/finger_r.STL"/>
            </geometry>
        </collision>
    </link>
    <joint name="joint_6" type="prismatic">
        <origin rpy="0 0 0" xyz="0.07285 0 0.0050143"/>
        <parent link="gripper_link"/>
        <child link="finger_r"/>
        <axis xyz="0 1 0"/>
        <limit effort="1" lower="-1" upper="0" velocity="1"/>
    </joint>
    <link name="finger_l">
        <inertial>
            <origin rpy="0 0 0" xyz="0.0100191599590265 0.00643833435729511 -0.00483280251641866"/>
            <mass value="0.0121931459003603"/>
            <inertia ixx="6.74017180959932E-07" ixy="2.3646368440071E-07" ixz="3.14801230297432E-09" iyy="3.10966207084492E-06" iyz="-1.19277023229564E-10" izz="2.77935600332313E-06"/>
        </inertial>
        <visual>
            <origin rpy="0 0 0" xyz="0 0 0"/>
            <geometry>
                <mesh filename="package://locobot_description/meshes/finger_l.STL"/>
            </geometry>
            <material name="">
                <color rgba="0.792156862745098 0.819607843137255 0.933333333333333 1"/>
            </material>
        </visual>
        <collision>
            <origin rpy="0 0 0" xyz="0 0 0"/>
            <geometry>
                <mesh filename="package://locobot_description/meshes/finger_l.STL"/>
            </geometry>
        </collision>
    </link>
    <joint name="joint_7" type="prismatic">
        <origin rpy="0 0 0" xyz="0.07285 0 0.0050143"/>
        <parent link="gripper_link"/>
        <child link="finger_l"/>
        <axis xyz="0 1 0"/>
        <limit effort="1" lower="0" upper="1" velocity="1"/>
    </joint>
    <link name="ar_tag">
        <inertial>
            <origin rpy="0 0 0" xyz="-1.59182528269852E-09 1.70641183422241E-09 -0.00509579048106218"/>
            <mass value="0.0202622634619862"/>
            <inertia ixx="4.71058333074219E-06" ixy="3.03778067070489E-12" ixz="6.65421687578365E-13" iyy="4.05773489073818E-06" iyz="1.37033485576347E-13" izz="7.92378853658606E-06"/>
        </inertial>
        <visual>
            <origin rpy="0 0 0" xyz="0 0 0"/>
            <geometry>
                <mesh filename="package://locobot_description/meshes/ar_tag.STL"/>
            </geometry>
            <material name="">
                <color rgba="0.792156862745098 0.819607843137255 0.933333333333333 1"/>
            </material>
        </visual>
        <collision>
            <origin rpy="0 0 0" xyz="0 0 0"/>
            <geometry>
                <mesh filename="package://locobot_description/meshes/ar_tag.STL"/>
            </geometry>
        </collision>
    </link>
    <joint name="ar_tag_joint" type="fixed">
        <origin rpy="0 0 0" xyz="0.0269499999999999 0 0.04315"/>
        <parent link="gripper_link"/>
        <child link="ar_tag"/>
        <axis xyz="0 0 0"/>
    </joint>
    <!-- Gazebo Plugins -->
    <gazebo>
        <plugin filename="libgazebo_ros_control.so" name="gazebo_ros_control">
            <robotNamespace>/</robotNamespace>
            <legacyModeNS>true</legacyModeNS>
        </plugin>
    </gazebo>
    <!-- Camera joints -->
    <transmission name="tran_head_tilt">
        <type>transmission_interface/SimpleTransmission</type>
        <joint name="head_tilt_joint">
            <hardwareInterface>hardware_interface/EffortJointInterface</hardwareInterface>
        </joint>
        <actuator name="head_tilt_motor">
            <hardwareInterface>hardware_interface/EffortJointInterface</hardwareInterface>
            <mechanicalReduction>1</mechanicalReduction>
        </actuator>
    </transmission>
    <transmission name="tran_head_pan">
        <type>transmission_interface/SimpleTransmission</type>
        <joint name="head_pan_joint">
            <hardwareInterface>hardware_interface/EffortJointInterface</hardwareInterface>
        </joint>
        <actuator name="head_pan_motor">
            <hardwareInterface>hardware_interface/EffortJointInterface</hardwareInterface>
            <mechanicalReduction>1</mechanicalReduction>
        </actuator>
    </transmission>
    <!-- Arm joints -->
    <transmission name="tran_1">
        <type>transmission_interface/SimpleTransmission</type>
        <joint name="joint_1">
            <hardwareInterface>hardware_interface/EffortJointInterface</hardwareInterface>
        </joint>
        <actuator name="motor_1">
            <hardwareInterface>hardware_interface/EffortJointInterface</hardwareInterface>
            <mechanicalReduction>1</mechanicalReduction>
        </actuator>
    </transmission>
    <transmission name="tran_2">
        <type>transmission_interface/SimpleTransmission</type>
        <joint name="joint_2">
            <hardwareInterface>hardware_interface/EffortJointInterface</hardwareInterface>
        </joint>
        <actuator name="motor_2">
            <hardwareInterface>hardware_interface/EffortJointInterface</hardwareInterface>
            <mechanicalReduction>1</mechanicalReduction>
        </actuator>
    </transmission>
    <transmission name="tran_3">
        <type>transmission_interface/SimpleTransmission</type>
        <joint name="joint_3">
            <hardwareInterface>hardware_interface/EffortJointInterface</hardwareInterface>
        </joint>
        <actuator name="motor_3">
            <hardwareInterface>hardware_interface/EffortJointInterface</hardwareInterface>
            <mechanicalReduction>1</mechanicalReduction>
        </actuator>
    </transmission>
    <transmission name="tran_4">
        <type>transmission_interface/SimpleTransmission</type>
        <joint name="joint_4">
            <hardwareInterface>hardware_interface/EffortJointInterface</hardwareInterface>
        </joint>
        <actuator name="motor_4">
            <hardwareInterface>hardware_interface/EffortJointInterface</hardwareInterface>
            <mechanicalReduction>1</mechanicalReduction>
        </actuator>
    </transmission>
    <transmission name="tran_5">
        <type>transmission_interface/SimpleTransmission</type>
        <joint name="joint_5">
            <hardwareInterface>hardware_interface/EffortJointInterface</hardwareInterface>
        </joint>
        <actuator name="motor_5">
            <hardwareInterface>hardware_interface/EffortJointInterface</hardwareInterface>
            <mechanicalReduction>1</mechanicalReduction>
        </actuator>
    </transmission>
    <transmission name="tran_6">
        <type>transmission_interface/SimpleTransmission</type>
        <joint name="joint_6">
            <hardwareInterface>hardware_interface/EffortJointInterface</hardwareInterface>
        </joint>
        <actuator name="motor_6">
            <hardwareInterface>hardware_interface/EffortJointInterface</hardwareInterface>
            <mechanicalReduction>1</mechanicalReduction>
        </actuator>
    </transmission>
    <transmission name="tran_7">
        <type>transmission_interface/SimpleTransmission</type>
        <joint name="joint_7">
            <hardwareInterface>hardware_interface/EffortJointInterface</hardwareInterface>
        </joint>
        <actuator name="motor_7">
            <hardwareInterface>hardware_interface/EffortJointInterface</hardwareInterface>
            <mechanicalReduction>1</mechanicalReduction>
        </actuator>
    </transmission>
    <!-- camera -->
    <gazebo reference="camera_link">
        <sensor name="camera_frame_sensor" type="depth">
            <always_on>true</always_on>
            <update_rate>30.0</update_rate>
            <camera>
                <horizontal_fov>0.994837</horizontal_fov>
                <image>
                    <format>R8G8B8</format>
                    <width>640</width>
                    <height>480</height>
                </image>
                <clip>
                    <near>0.01</near>
                    <far>10</far>
                </clip>
            </camera>
            <plugin filename="libgazebo_ros_openni_kinect.so" name="camera_frame_controller">
                <alwaysOn>true</alwaysOn>
                <updateRate>30.0</updateRate>
                <cameraName>camera</cameraName>
                <imageTopicName>color/image_raw</imageTopicName>
                <cameraInfoTopicName>color/camera_info</cameraInfoTopicName>
                <depthImageTopicName>aligned_depth_to_color/image_raw</depthImageTopicName>
                <depthImageCameraInfoTopicName>aligned_depth_to_color/camera_info</depthImageCameraInfoTopicName>
                <pointCloudTopicName>depth_registered/points</pointCloudTopicName>
                <frameName>camera_color_optical_frame</frameName>
                <pointCloudCutoff>10</pointCloudCutoff>
                <distortionK1>0.00000001</distortionK1>
                <distortionK2>0.00000001</distortionK2>
                <distortionK3>0.00000001</distortionK3>
                <distortionT1>0.00000001</distortionT1>
                <distortionT2>0.00000001</distortionT2>
                <CxPrime>0</CxPrime>
                <Cx>0</Cx>
                <Cy>0</Cy>
                <focalLength>0</focalLength>
                <hackBaseline>0</hackBaseline>
            </plugin>
        </sensor>
    </gazebo>
    <gazebo reference="bottom_plate">
        <self_collide>true</self_collide>
    </gazebo>
    <!-- Gazebo plugins for the base of the robot -->
    <gazebo>
        <plugin filename="libgazebo_ros_diff_drive.so" name="differential_drive_controller">
            <alwaysOn>true</alwaysOn>
            <legacyMode>false</legacyMode>
            <updateRate>40</updateRate>
            <leftJoint>left_wheel_joint</leftJoint>
            <rightJoint>right_wheel_joint</rightJoint>
            <wheelSeparation>0.235</wheelSeparation>
            <wheelDiameter>0.072</wheelDiameter>
            <wheelTorque>1.0</wheelTorque>
            <!--wheelAcceleration>${wheel_accel}</wheelAcceleration-->
            <commandTopic>cmd_vel</commandTopic>
            <odometryTopic>odom</odometryTopic>
            <odometryFrame>odom</odometryFrame>
            <robotBaseFrame>base_footprint</robotBaseFrame>
        </plugin>
        <plugin filename="libgazebo_ros_p3d.so" name="p3d_base_controller">
            <alwaysOn>true</alwaysOn>
            <updateRate>100.0</updateRate>
            <bodyName>base_link</bodyName>
            <topicName>base/absolute_position</topicName>
            <gaussianNoise>0</gaussianNoise>
            <frameName>map</frameName>
            <xyzOffsets>0 0 0</xyzOffsets>
            <rpyOffsets>0 0 0</rpyOffsets>
            <!--<interface:position name="p3d_base_position"/>-->
        </plugin>
    </gazebo>
    <gazebo reference="left_wheel_link">
        <mu1>1.0</mu1>
        <mu2>1.0</mu2>
        <kp>1000000.0</kp>
        <kd>100.0</kd>
        <minDepth>0.001</minDepth>
        <maxVel>1.0</maxVel>
    </gazebo>
    <gazebo reference="right_wheel_link">
        <mu1>1.0</mu1>
        <mu2>1.0</mu2>
        <kp>1000000.0</kp>
        <kd>100.0</kd>
        <minDepth>0.001</minDepth>
        <maxVel>1.0</maxVel>
    </gazebo>
    <gazebo reference="rear_wheel_link">
        <mu1>0.0</mu1>
        <mu2>0.0</mu2>
        <kp>1000000.0</kp>
        <kd>100.0</kd>
        <minDepth>0.001</minDepth>
        <maxVel>1.0</maxVel>
    </gazebo>
    <gazebo reference="front_wheel_link">
        <mu1>0.0</mu1>
        <mu2>0.0</mu2>
        <kp>1000000.0</kp>
        <kd>100.0</kd>
        <minDepth>0.001</minDepth>
        <maxVel>1.0</maxVel>
    </gazebo>
    <gazebo reference="wall_sensor_link">
        <sensor name="wall_sensor" type="ray">
            <always_on>true</always_on>
            <update_rate>20.0</update_rate>
            <pose>0 0 0 0 0 0</pose>
            <visualize>false</visualize>
            <ray>
                <scan>
                    <horizontal>
                        <samples>1</samples>
                        <resolution>1</resolution>
                        <min_angle>0</min_angle>
                        <max_angle>0</max_angle>
                    </horizontal>
                </scan>
                <range>
                    <min>0.0160</min>
                    <max>0.04</max>
                    <resolution>0.1</resolution>
                </range>
            </ray>
        </sensor>
    </gazebo>
    <gazebo reference="left_cliff_sensor_link">
        <sensor name="left_cliff_sensor" type="ray">
            <always_on>true</always_on>
            <update_rate>20.0</update_rate>
            <pose>0 0 0 0 0 0</pose>
            <visualize>false</visualize>
            <ray>
                <scan>
                    <horizontal>
                        <samples>1</samples>
                        <resolution>1</resolution>
                        <min_angle>0</min_angle>
                        <max_angle>0</max_angle>
                    </horizontal>
                </scan>
                <range>
                    <min>0.01</min>
                    <max>0.04</max>
                    <resolution>0.1</resolution>
                </range>
            </ray>
        </sensor>
    </gazebo>
    <gazebo reference="right_cliff_sensor_link">
        <sensor name="right_cliff_sensor" type="ray">
            <always_on>true</always_on>
            <update_rate>20.0</update_rate>
            <pose>0 0 0 0 0 0</pose>
            <visualize>false</visualize>
            <ray>
                <scan>
                    <horizontal>
                        <samples>1</samples>
                        <resolution>1</resolution>
                        <min_angle>0</min_angle>
                        <max_angle>0</max_angle>
                    </horizontal>
                </scan>
                <range>
                    <min>0.01</min>
                    <max>0.04</max>
                    <resolution>0.1</resolution>
                </range>
            </ray>
        </sensor>
    </gazebo>
    <gazebo reference="leftfront_cliff_sensor_link">
        <sensor name="leftfront_cliff_sensor" type="ray">
            <always_on>true</always_on>
            <update_rate>20.0</update_rate>
            <pose>0 0 0 0 0 0</pose>
            <visualize>false</visualize>
            <ray>
                <scan>
                    <horizontal>
                        <samples>1</samples>
                        <resolution>1</resolution>
                        <min_angle>0</min_angle>
                        <max_angle>0</max_angle>
                    </horizontal>
                </scan>
                <range>
                    <min>0.01</min>
                    <max>0.04</max>
                    <resolution>0.1</resolution>
                </range>
            </ray>
        </sensor>
    </gazebo>
    <gazebo reference="rightfront_cliff_sensor_link">
        <sensor name="rightfront_cliff_sensor" type="ray">
            <always_on>true</always_on>
            <update_rate>20.0</update_rate>
            <pose>0 0 0 0 0 0</pose>
            <visualize>false</visualize>
            <ray>
                <scan>
                    <horizontal>
                        <samples>1</samples>
                        <resolution>1</resolution>
                        <min_angle>0</min_angle>
                        <max_angle>0</max_angle>
                    </horizontal>
                </scan>
                <range>
                    <min>0.01</min>
                    <max>0.04</max>
                    <resolution>0.1</resolution>
                </range>
            </ray>
        </sensor>
    </gazebo>
    <gazebo>
        <plugin filename="libgazebo_ros_imu.so" name="imu_controller">
            <alwaysOn>true</alwaysOn>
            <updateRate>30</updateRate>
            <bodyName>gyro_link</bodyName>
            <topicName>create/imu/data</topicName>
            <serviceName>create/imu/is_calibrated</serviceName>
            <gaussianNoise>2.89e-06</gaussianNoise>
            <xyzOffsets>0 0 0</xyzOffsets>
            <rpyOffsets>0 0 0</rpyOffsets>
        </plugin>
    </gazebo>
</robot>
